Workbook

Sheet Executive Dashboard
A1: NATIONS ROOF AI TRANSFORMATION - EXECUTIVE DASHBOARD
A3: TRANSFORMATION OVERVIEW
A4: Metric | B4: Current State | C4: Post-Transform | D4: Change | E4: % Change
A5: Total Annual Benefit | B5: - | C5: ='Consolidated'!B25 | D5: ='Consolidated'!B25 | E5: -
A6: Annual Revenue | B6: ='Company Baseline'!B7 | C6: ='Consolidated'!C32 | D6: =C6-B6 | E6: =D6/B6
A7: Win Rate | B7: ='Company Baseline'!B17 | C7: ='Consolidated'!C33 | D7: =C7-B7 | E7: =D7/B7
A8: Net Income | B8: ='Company Baseline'!B11 | C8: ='Consolidated'!C34 | D8: =C8-B8 | E8: =D8/B8
A9: Net Margin | B9: ='Company Baseline'!B9 | C9: ='Consolidated'!C35 | D9: =C9-B9 | E9: =D9/B9
A10: Annual Projects | B10: ='Company Baseline'!B15 | C10: ='Consolidated'!C36 | D10: =C10-B10 | E10: =D10/B10
A11: Leads Generated | B11: ='Company Baseline'!B21 | C11: ='Consolidated'!C37 | D11: =C11-B11 | E11: =D11/B11
A12: Cost Per Lead | B12: ='Company Baseline'!B22 | C12: ='Consolidated'!C38 | D12: =C12-B12 | E12: =D12/B12
A15: PLATFORM FINANCIAL SUMMARY
A16: Platform | B16: Revenue Growth | C16: Cost Reduction | D16: Risk Reduction | E16: Cash Flow | F16: Total Benefit | G16: % of Total
A17: P0: AI Market Expansion Engine | B17: ='Platform 0'!C58 | C17: ='Platform 0'!C59 | D17: ='Platform 0'!C61 | E17: ='Platform 0'!C60 | F17: ='Platform 0'!C62 | G17: =F17/$F$22
A18: P1: AI Sales Intelligence | B18: ='Platform 1'!C51 | C18: ='Platform 1'!C52 | D18: 0 | E18: 0 | F18: ='Platform 1'!C53 | G18: =F18/$F$22
A19: P2: AI Estimation Suite | B19: ='Platform 2'!C55 | C19: ='Platform 2'!C54 | D19: ='Platform 2'!C56 | E19: ='Platform 2'!C57 | F19: ='Platform 2'!C58 | G19: =F19/$F$22
A20: P3: AI Project Management | B20: ='Platform 3'!C55 | C20: ='Platform 3'!C54 | D20: 0 | E20: ='Platform 3'!C56 | F20: ='Platform 3'!C57 | G20: =F20/$F$22
A21: P4: AI Knowledge Management | B21: ='Platform 4'!C41 | C21: ='Platform 4'!C40 | D21: 0 | E21: 0 | F21: ='Platform 4'!C42 | G21: =F21/$F$22
A22: GRAND TOTAL | B22: =SUM(B17:B21) | C22: =SUM(C17:C21) | D22: =SUM(D17:D21) | E22: =SUM(E17:E21) | F22: =SUM(F17:F21) | G22: 100%
A25: BENEFIT BY BUSINESS DRIVER
A26: Business Driver | B26: Annual Benefit | C26: % of Total | D26: Primary Platforms
A27: Revenue Growth | B27: 76200000 | C27: =B27/SUM($B$27:$B$30) | D27: P0, P1, P2, P3
A28: Cost Reduction | B28: 28600000 | C28: =B28/SUM($B$27:$B$30) | D28: P0, P2, P3, P4
A29: Risk Mitigation | B29: 4400000 | C29: =B29/SUM($B$27:$B$30) | D29: P0, P2, P4
A30: Cash Flow Improvement | B30: 2700000 | C30: =B30/SUM($B$27:$B$30) | D30: P0, P2, P3
A31: TOTAL | B31: =SUM(B27:B30) | C31: 100%

Sheet Company Baseline
A1: COMPANY BASELINE - CURRENT STATE METRICS
A3: Instructions: Modify YELLOW cells to adjust baseline assumptions. All platforms reference these values.
A5: FINANCIAL METRICS
A6: Metric | B6: Value | C6: Unit | D6: Formula/Source | E6: Notes
A7: Annual Revenue | B7: 527000000 | C7: USD | D7: Input | E7: FY2024 total revenue
A8: Gross Margin % | B8: 0.35 | C8: % | D8: Input | E8: 35% gross margin
A9: Net Margin % | B9: 0.07 | C9: % | D9: Input | E9: 7% net margin
A10: Gross Profit | B10: =B7*B8 | C10: USD | D10: =Revenue × Gross Margin | E10: Calculated
A11: Net Income | B11: =B7*B9 | C11: USD | D11: =Revenue × Net Margin | E11: Calculated
A13: OPERATIONAL METRICS
A14: Metric | B14: Value | C14: Unit | D14: Formula/Source | E14: Notes
A15: Annual Projects Completed | B15: 2100 | C15: # | D15: Input | E15: Projects delivered per year
A16: Annual Bids Submitted | B16: 11700 | C16: # | D16: Input | E16: Total bids per year
A17: Current Win Rate | B17: =B15/B16 | C17: % | D17: =Projects / Bids | E17: 18% win rate
A18: Average Project Value | B18: 250000 | C18: USD | D18: Input | E18: Average commercial roofing project
A19: Typical Project Duration | B19: 45 | C19: days | D19: Input | E19: 1-2 month average
A20: Daily Revenue per Project | B20: =B18/B19 | C20: USD | D20: =Avg Value / Duration | E20: Calculated
A22: LEAD GENERATION METRICS (CURRENT STATE)
A23: Metric | B23: Value | C23: Unit | D23: Formula/Source | E23: Notes
A24: Current Annual Leads | B24: 2400 | C24: # | D24: Input | E24: ~200/month × 12
A25: Current Cost Per Lead | B25: 350 | C25: USD | D25: Input | E25: Industry average
A26: Current Lead Spend | B26: =B24*B25 | C26: USD | D26: =Leads × CPL | E26: Calculated
A27: Lead-to-Project Conversion | B27: =B15/B24 | C27: % | D27: =Projects / Leads | E27: Calculated
A28: Speed to Lead (Current) | B28: 240 | C28: minutes | D28: Input | E28: 4 hours average
A30: WORKFORCE METRICS
A31: Role | B31: Headcount | C31: Hourly Rate | D31: Annual Hours | E31: Annual Cost
A32: Estimators | B32: 25 | C32: 75 | D32: 2080 | E32: =B32*C32*D32
A33: Project Managers | B33: 45 | C33: 75 | D33: 2080 | E33: =B33*C33*D33
A34: Sales Representatives | B34: 30 | C34: 75 | D34: 2080 | E34: =B34*C34*D34
A35: SDRs (Sales Dev Reps) | B35: 15 | C35: 50 | D35: 2080 | E35: =B35*C35*D35
A36: TOTAL WORKFORCE COST | E36: =SUM(E32:E35)

Sheet Platform 0
A1: PLATFORM 0: AI MARKET EXPANSION ENGINE
A2: Autonomous Agent Swarm for Lead Generation and Sales Acceleration
A3: Annual Financial Benefit: $35,000,000
A5: STEP 2: FRICTION POINT INVENTORY (Current State Problems)
A6: Friction Category | B6: Specific Issue | C6: Business Impact | D6: Annual Cost
A7: Speed to Lead | B7: Inbound leads sit in CRM inboxes for hours; conversion drops 80% after 5 minutes | C7: Lost conversions | D7: 4200000
A8: Manual List Building | B8: SDRs waste 40% of time scraping permit sites and hail maps instead of selling | C8: 35% of sales time lost | D8: 2400000
A9: Knowledge Gaps | B9: Junior reps struggle to answer technical questions (TPO vs EPDM), losing credibility | C9: Poor qualification | D9: 1500000
A10: Data Silos | B10: Salesforce CRM disconnected from property, weather, permit data | C10: Missed timing | D10: 1200000
A11: Seasonal Peaks | B11: Storm events create surge demand; can't scale manual outreach | C11: Lost emergency revenue | D11: 2800000
A12: Customer Experience | B12: Inconsistent follow-up; leads go cold | C12: 40% lead leakage | D12: 3800000
A13: TOTAL FRICTION COST | D13: =SUM(D7:D12)
A15: STEP 3: THE SOLUTION - Autonomous Agent Swarm
A16: Agent | B16: Role & Responsibility | C16: Trigger & Action | D16: Technology
A17: THE SCOUT (Data Agent) | B17: Monitors new data sources (Hail maps, Permits, Property records). Identifies high-value targets matching ICP. | C17: Triggers alerts: 'Hail in Dallas—47 properties affected.' Creates CRM leads automatically in Salesforce. | D17: Web scrapers, APIs, ML classification
A18: THE HUNTER (Outbound Agent) | B18: Takes leads from The Scout. Generates hyper-personalized messages. Executes multi-channel campaigns. | C18: 'Saw your roof age is 20y and recent hail activity...' Campaigns via Email, SMS, LinkedIn—24/7 operation. | D18: LLM content generation, campaign automation
A19: THE CONCIERGE (Inbound Agent) | B19: Lives on website/SMS. Qualifies inbound traffic 24/7. Answers technical questions (TPO vs EPDM) with RAG knowledge. | C19: 'Do you have a leak?' → 'Let me get a truck rolled.' Instant <2 minute response regardless of time. | D19: RAG, LLM chat, website integration
A20: THE CLOSER (Scheduling Agent) | B20: Accesses human estimator calendars. Negotiates times, sends invites, handles rescheduling autonomously. | C20: Books meetings directly on calendar. Qualified leads handed off to Platform 1 (Sales Intelligence). | D20: Calendar API, constraint optimization
A22: DATA SOURCES (Fueling the Engine)
A23: Data Source | B23: Provider | C23: Trigger Use Case | D23: Annual Cost
A24: Hail & Storm Data | B24: HailTrace / Interactive Maps / AccuWeather | C24: Emergency Service campaigns immediately after storms | D24: 45000
A25: Building Permits | B25: ConstructConnect / Dodge Data | C25: New Roof bids based on active permits and project starts | D25: 85000
A26: Property Records | B26: CoStar / Reonomy / LoopNet | C26: Reroof opportunities—property age >15y or ownership changes | D26: 120000
A27: Contact Enrichment | B27: ZoomInfo / Apollo / Lusha | C27: Decision-maker identification and contact data | D27: 95000
A28: Intent Signals | B28: Bombora / TrustRadius | C28: Identify companies researching roofing services | D28: 65000
A29: TOTAL DATA INVESTMENT | D29: =SUM(D24:D28)
A31: INPUT PARAMETERS (Modify to see impact)
A32: Parameter | B32: Value | C32: Unit | D32: Description
A33: Annual Leads Generated | B33: 10000 | C33: # | D33: Target leads from AI agent swarm
A34: Lead-to-Meeting Conversion Rate | B34: 0.12 | C34: % | D34: 12% conversion (industry: 5.58%)
A35: Meeting-to-Close Rate | B35: 0.2 | C35: % | D35: 20% of meetings become projects
A36: Target Cost Per Lead | B36: 120 | C36: USD | D36: Reduced from $350 baseline
A37: Maintenance Plan Attach Rate | B37: 0.25 | C37: % | D37: 25% of new projects add maintenance
A38: Maintenance Plan Annual Value | B38: 25000 | C38: USD | D38: Average annual maintenance contract
A39: Sales Cycle Reduction | B39: 14 | C39: days | D39: Days saved in sales cycle
A40: Platform Development Cost | B40: 1200000 | C40: USD | D40: One-time investment
A42: STEP 5: KPI DASHBOARD vs. Industry Benchmarks
A43: KPI | B43: Baseline (Manual) | C43: Target (AI Agent) | D43: Industry Benchmark | E43: Improvement
A44: Speed to Lead | B44: 4 hours | C44: <2 minutes | D44: 5 minutes | E44: =1-2/(4*60)
A45: Cost Per Lead (CPL) | B45: ='Company Baseline'!B25 | C45: =B36 | D45: 350 | E45: =1-C44/B44
...

Sheet Platform 1
A1: PLATFORM 1: AI SALES INTELLIGENCE
A2: Intelligent Bid Selection and Competitive Analysis
A3: Annual Financial Benefit: $24,195,000
A5: STEP 2: FRICTION POINT INVENTORY
A6: Friction Category | B6: Specific Issue | C6: Business Impact | D6: Annual Cost
A7: Knowledge Gaps | B7: No visibility into which bids to pursue vs. walk away | C7: 22% win rate (below potential) | D7: 14400000
A8: Data Silos | B8: Competitor pricing/strategies unknown | C8: Losing winnable deals | D8: 7200000
A9: Low-Value Work | B9: Manual competitor research takes 3+ hours per bid | C9: Reduced bid capacity | D9: 2100000
A10: TOTAL FRICTION COST | D10: =SUM(D7:D9)
A12: STEP 3: USE CASE MAPPING
A13: ID | B13: Use Case | C13: Workflow Description | D13: Primary Value
A14: 25 | B14: Bid Assignment AI | C14: AI scores opportunities in Salesforce, matches to team strengths, recommends pursue/pass | D14: Optimal bid selection
A15: 23 | B15: Competitor Proposal Analysis | C15: AI analyzes historical competitor proposals to identify patterns | D15: Competitive intelligence
A16: 24 | B16: Competitor Info Scouting | C16: AI monitors competitor activities, pricing, market moves | D16: Market intelligence
A18: INPUT PARAMETERS
A19: Parameter | B19: Value | C19: Unit | D19: Description
A20: Win Rate Improvement | B20: 11 | C20: pts | D20: Percentage points improvement (22% → 33%)
A21: Bid Evaluation Time - Current | B21: 3 | C21: hrs | D21: Hours per bid currently
A22: Bid Evaluation Time - With AI | B22: 0.5 | C22: hrs | D22: Hours per bid with AI
A23: Bid Assignment Attribution | B23: 0.55 | C23: % | D23: 55% of improvement from bid assignment (6 pts)
A24: Competitor Analysis Attribution | B24: 0.27 | C24: % | D24: 27% from competitor analysis (3 pts)
A25: Competitor Scouting Attribution | B25: 0.09 | C25: % | D25: 9% from competitor scouting (1 pt)
A26: Edge Reviews Attribution (P2) | B26: 0.09 | C26: % | D26: 9% from Platform 2 (1 pt)
A28: STEP 5: KPI DEFINITIONS
A29: Use Case | B29: KPI | C29: Baseline | D29: Target | E29: Improvement
A30: Bid Assignment | B30: Win Rate | C30: ='Company Baseline'!B17 | D30: =C30+B20/100 | E30: =D30/C30-1
A31: Bid Assignment | B31: Bid evaluation time (hours) | C31: =B21 | D31: =B22 | E31: =1-D31/C31
A32: Competitor Analysis | B32: Competitive insights/bid | C32: 2 | D32: 8 | E32: =D32/C32-1
A33: Competitor Scouting | B33: Market intel updates/week | C33: 1 | D33: 7 | E33: =D33/C33-1
A35: STEP 6: FINANCIAL CALCULATIONS
A36: Calculation Step | B36: Formula | C36: Result | D36: Unit
A37: Current Win Rate | B37: From Company Baseline | C37: ='Company Baseline'!B17 | D37: %
A38: New Win Rate | B38: =Current + Improvement pts | C38: =C37+B20/100 | D38: %
A39: Additional Wins per Year | B39: =Bids × Improvement % | C39: ='Company Baseline'!B16*B20/100 | D39: #
A40: Time Saved per Bid (hrs) | B40: =Current - AI Time | C40: =B21-B22 | D40: hrs
A41: Total Hours Saved per Year | B41: =Bids × Hours Saved | C41: ='Company Baseline'!B16*C40 | D41: hrs
A42: Revenue per Additional Win | B42: =Avg Project × Gross Margin | C42: ='Company Baseline'!B18*'Company Baseline'!B8 | D42: USD
A43: Total Revenue from Wins | B43: =Additional Wins × Revenue Each | C43: =C39*C42 | D43: USD
A44: Labor Cost Savings | B44: =Hours Saved × Hourly Rate | C44: =C41*'Company Baseline'!C32 | D44: USD
A46: USE CASE FINANCIAL BREAKDOWN
...

Sheet Platform 2
A1: PLATFORM 2: AI ESTIMATION SUITE
A2: Automated Proposal Creation and Specification Analysis
A3: Annual Financial Benefit: $23,210,000
A5: STEP 2: FRICTION POINT INVENTORY
A6: Friction Category | B6: Specific Issue | C6: Business Impact | D6: Annual Cost
A7: Low-Value Repetitive Work | B7: NR Bid Sheet and proposal creation takes 2.5 hours each | C7: 14,000 hours/year | D7: 6700000
A8: Knowledge Gaps | B8: Edge Estimate difficult to use with steep learning curve; creates estimates from hand-drawn Takeoffs | C8: Bottleneck on experts | D8: 5100000
A9: Rework and Errors | B9: Takeoff errors (measurements, quantities, roof depth, pipes, curbing, skylights) | C9: Project overruns | D9: 4400000
A10: Compliance Gaps | B10: Vendor quotes don't always match spec requirements; labor rates vary by region | C10: Material mismatches | D10: 3600000
A11: TOTAL FRICTION COST | D11: =SUM(D7:D10)
A13: STEP 3: USE CASE MAPPING
A14: ID | B14: Use Case | C14: Workflow Description | D14: Primary Value
A15: 5 | B15: Proposal Creation | C15: AI generates NR Bid Sheet and proposals from Edge data; handles regional labor rates | D15: 87% time reduction
A16: 1 | B16: Specification Reviews | C16: AI extracts requirements from specs; flags gaps and conflicts | D16: 83% time reduction
A17: 2 | B17: Edge Estimate Reviews | C17: AI validates estimates from Edge against historical data and Takeoff details | D17: Accuracy improvement
A18: 11 | B18: Compare Quotes to Specs | C18: AI matches vendor quotes to spec requirements; flags mismatches | D18: Risk reduction
A19: 4 | B19: Proposal Evaluation | C19: AI analyzes competitor proposals for patterns and pricing | D19: Competitive insight
A20: 3 | B20: Technical Questions | C20: AI answers estimator questions using knowledge base (addresses Edge learning curve) | D20: Expert availability
A22: STEP 5: KPI DEFINITIONS
A23: Use Case | B23: KPI | C23: Baseline | D23: Target | E23: Improvement
A24: Proposal Creation | B24: Creation time (hours) | C24: 2.5 | D24: 0.33 | E24: =1-D24/C24
A25: Spec Reviews | B25: Review time (hours) | C25: 3 | D25: 0.5 | E25: =1-D25/C25
A26: Edge Reviews | B26: Estimate error rate | C26: 0.08 | D26: 0.02 | E26: =1-D26/C26
A27: Quote Comparison | B27: Spec-quote match rate | C27: 0.85 | D27: 0.98 | E27: =(D27-C27)/C27
A28: Technical Q&A | B28: Response time (hours) | C28: 4 | D28: 0.25 | E28: =1-D28/C28
A30: STEP 6: FINANCIAL IMPACT BY USE CASE
A31: ID | B31: Use Case | C31: Labor | D31: Revenue | E31: Risk | F31: Cash | G31: Total
A32: 5 | B32: Proposal Creation | C32: 1336000 | D32: 4585000 | E32: 0 | F32: 800000 | G32: =SUM(C32:F32)
A33: 1 | B33: Specification Reviews | C33: 660000 | D33: 3780000 | E33: 700000 | F33: 0 | G33: =SUM(C33:F33)
A34: 2 | B34: Edge Estimate Reviews | C34: 308000 | D34: 4095000 | E34: 0 | F34: 0 | G34: =SUM(C34:F34)
A35: 11 | B35: Compare Quotes/Specs | C35: 330000 | D35: 0 | E35: 3240000 | F35: 0 | G35: =SUM(C35:F35)
A36: 4 | B36: Proposal Evaluation | C36: 225000 | D36: 1838000 | E36: 0 | F36: 0 | G36: =SUM(C36:F36)
A37: 3 | B37: Technical Questions | C37: 858000 | D37: 455000 | E37: 0 | F37: 0 | G37: =SUM(C37:F37)
A38: TOTALS | C38: =SUM(C32:C37) | D38: =SUM(D32:D37) | E38: =SUM(E32:E37) | F38: =SUM(F32:F37) | G38: =SUM(G32:G37)
A40: PLATFORM 2 SUMMARY
A41: Category | B41: Cell Reference | C41: Value
A42: Total Labor Savings | B42: =C38 | C42: =C38
A43: Total Revenue Growth | B43: =D38 | C43: =D38
A44: Total Risk Reduction | B44: =E38 | C44: =E38
A45: Total Cash Flow | B45: =F38 | C45: =F38
...

Sheet Platform 3
A1: PLATFORM 3: AI PROJECT MANAGEMENT
A2: Seamless Project Delivery and Customer Experience
A3: Annual Financial Benefit: $21,585,000
A5: STEP 2: FRICTION POINT INVENTORY
A6: Friction Category | B6: Specific Issue | C6: Business Impact | D6: Annual Cost
A7: Delays and Handoffs | B7: Projects delayed average 12 days; schedule creation takes 10 hours | C7: LD penalties, overhead | D7: 9800000
A8: Rework and Errors | B8: Actuals vs estimates not tracked until project end | C8: Surprise overruns | D8: 2900000
A9: Low-Value Work | B9: Daily/weekly reports for customers and field crews consume PM time | C9: Reduced PM capacity | D9: 1800000
A10: Knowledge Gaps | B10: Project Portfolio assembly manual; Pre-Con Packets created manually | C10: Inconsistent delivery | D10: 1500000
A11: Customer Experience | B11: Customers like Walmart require Service Channel geofencing compliance | C11: SLA/KPI penalties | D11: 800000
A12: TOTAL FRICTION COST | D12: =SUM(D7:D11)
A14: STEP 3: USE CASE MAPPING
A15: ID | B15: Use Case | C15: Workflow Description | D15: Primary Value
A16: 18 | B16: Schedule Generation | C16: AI optimizes schedules considering resources, weather, ADP/Service Channel | D16: 75% time reduction
A17: 10 | B17: BU Actual vs Estimate | C17: AI tracks actuals in real-time from Viewpoint; alerts on variances | D17: Early intervention
A18: 15 | B18: RFI Response Generation | C18: AI drafts RFI responses using project context and knowledge base | D18: Faster turnaround
A19: 17 | B19: Project Closeout Docs | C19: AI assembles closeout packages; ensures completeness | D19: Faster final payment
A20: 19 | B20: Daily/Weekly Reports | C20: AI generates reports for customers and field crews automatically | D20: Time savings
A21: NEW | B21: Pre-Con Packet Assembly | C21: AI creates Scope of Work (drawings, sketches, steps) and Schedule of Work | D21: Standardization
A22: NEW | B22: Project Portfolio | C22: AI assembles complete Project Portfolio for customer and Nations Roof team | D22: Customer experience
A24: STEP 5: KPI DEFINITIONS
A25: Use Case | B25: KPI | C25: Baseline | D25: Target | E25: Improvement
A26: Schedule Gen | B26: Creation time (hours) | C26: 10 | D26: 2.5 | E26: =1-D26/C26
A27: Schedule Gen | B27: Project delay (days) | C27: 12 | D27: 3 | E27: =1-D27/C27
A28: BU Analysis | B28: Variance detection (days) | C28: 30 | D28: 1 | E28: =1-D28/C28
A29: Closeout Docs | B29: Assembly time (hours) | C29: 2 | D29: 0.5 | E29: =1-D29/C29
A30: Daily/Weekly Reports | B30: Report creation (minutes) | C30: 45 | D30: 5 | E30: =1-D30/C30
A32: STEP 6: FINANCIAL IMPACT BY USE CASE
A33: ID | B33: Use Case | C33: Labor | D33: Cost Reduction | E33: Revenue | F33: Cash | G33: Total
A34: 18 | B34: Schedule Generation | C34: 94000 | D34: 9450000 | E34: 0 | F34: 0 | G34: =SUM(C34:F34)
A35: 10 | B35: BU Actual vs Estimate | C35: 107000 | D35: 2025000 | E35: 735000 | F35: 0 | G35: =SUM(C35:F35)
A36: 15 | B36: RFI Response Generation | C36: 284000 | D36: 1563000 | E36: 0 | F36: 0 | G36: =SUM(C36:F36)
A37: 17 | B37: Project Closeout Docs | C37: 202000 | D37: 150000 | E37: 0 | F37: 445000 | G37: =SUM(C37:F37)
A38: 19 | B38: Daily/Weekly Reports | C38: 580000 | D38: 0 | E38: 0 | F38: 0 | G38: =SUM(C38:F38)
A39: NEW | B39: Pre-Con Packets + Portfolio | C39: 700000 | D39: 0 | E39: 2000000 | F39: 750000 | G39: =SUM(C39:F39)
A40: TOTALS | C40: =SUM(C34:C39) | D40: =SUM(D34:D39) | E40: =SUM(E34:E39) | F40: =SUM(F34:F39) | G40: =SUM(G34:G39)
A42: PLATFORM 3 SUMMARY
A43: Category | B43: Cell Reference | C43: Value
A44: Total Labor Savings | B44: =C40 | C44: =C40
A45: Total Cost Reduction | B45: =D40 | C45: =D40
...

Sheet Platform 4
A1: PLATFORM 4: AI KNOWLEDGE MANAGEMENT
A2: Foundation Layer with RBAC and Data Classification
A3: Annual Financial Benefit: $7,900,000
A5: FOUNDATION LAYER RESPONSIBILITIES
A6: • Real-time knowledge access across Nations Roof's organization
A7: • Role-Based Access Control (RBAC) ensuring appropriate access by role
A8: • Data Classification to protect sensitive information and maintain compliance
A9: • Unified search and retrieval across all project documentation
A11: STEP 2: FRICTION POINT INVENTORY
A12: Friction Category | B12: Specific Issue | C12: Business Impact | D12: Annual Cost
A13: Low-Value Repetitive Work | B13: Submittal assembly: Assembly Letter, Warranty, Technical Info, Code Requirements (manual download) | C13: Hours of assembly | D13: 6500000
A14: Data Silos | B14: Spec requirements not linked to Edge items systematically | C14: Manual lookup errors | D14: 1400000
A15: TOTAL FRICTION COST | D15: =SUM(D13:D14)
A17: STEP 3: USE CASE MAPPING
A18: ID | B18: Use Case | C18: Workflow Description | D18: Primary Value
A19: 16 | B19: Submittal Package Assembly | C19: AI gathers required docs: Assembly Letter, Manufacturer Warranty, Technical Info, Code Requirements; automates downloads from manufacturer websites | D19: 85% time reduction
A20: 9 | B20: Spec-to-Edge Mapping | C20: AI links specification requirements to Edge line items automatically | D20: Infrastructure for accuracy
A22: STEP 5: KPI DEFINITIONS
A23: Use Case | B23: KPI | C23: Baseline | D23: Target | E23: Improvement
A24: Submittal Assembly | B24: Assembly time (hours) | C24: 13.5 | D24: 2 | E24: =1-D24/C24
A25: Submittal Assembly | B25: Completeness rate | C25: 0.88 | D25: 0.99 | E25: =(D25-C25)/C25
A26: Spec-to-Edge Mapping | B26: Mapping accuracy | C26: 0.75 | D26: 0.95 | E26: =(D26-C26)/C26
A28: STEP 6: FINANCIAL IMPACT BY USE CASE
A29: ID | B29: Use Case | C29: Labor Savings | D29: Revenue Growth | E29: Total
A30: 16 | B30: Submittal Package Assembly | C30: 3250000 | D30: 3250000 | E30: =C30+D30
A31: 9 | B31: Spec-to-Edge Mapping | C31: 720000 | D31: 680000 | E31: =C31+D31
A32: TOTALS | C32: =SUM(C30:C31) | D32: =SUM(D30:D31) | E32: =SUM(E30:E31)
A34: PLATFORM 4 SUMMARY
A35: Category | B35: Cell Reference | C35: Value
A36: Total Labor Savings | B36: =C32 | C36: =C32
A37: Total Revenue Growth | B37: =D32 | C37: =D32
A38: PLATFORM 4 TOTAL BENEFIT | B38: =E32 | C38: =E32

Sheet Consolidated
A1: CONSOLIDATED FINANCIAL SUMMARY
A3: ANNUAL BENEFIT BY PLATFORM
A4: Platform | B4: Revenue | C4: Cost Red. | D4: Risk Red. | E4: Cash | F4: Total | G4: % of Total
A5: P0: AI Market Expansion | B5: ='Platform 0'!C60 | C5: ='Platform 0'!C61 | D5: ='Platform 0'!C64 | E5: ='Platform 0'!C62 | F5: ='Platform 0'!C65 | G5: =F5/$F$10
A6: P1: AI Sales Intelligence | B6: ='Platform 1'!C55 | C6: ='Platform 1'!C54 | D6: 0 | E6: 0 | F6: ='Platform 1'!C56 | G6: =F6/$F$10
A7: P2: AI Estimation Suite | B7: ='Platform 2'!D38 | C7: ='Platform 2'!C38 | D7: ='Platform 2'!E38 | E7: ='Platform 2'!F38 | F7: ='Platform 2'!G38 | G7: =F7/$F$10
A8: P3: AI Project Management | B8: ='Platform 3'!E40 | C8: ='Platform 3'!C40+'Platform 3'!D40 | D8: 0 | E8: ='Platform 3'!F40 | F8: ='Platform 3'!G40 | G8: =F8/$F$10
A9: P4: AI Knowledge Management | B9: ='Platform 4'!D32 | C9: ='Platform 4'!C32 | D9: 0 | E9: 0 | F9: ='Platform 4'!E32 | G9: =F9/$F$10
A10: GRAND TOTAL | B10: =SUM(B5:B9) | C10: =SUM(C5:C9) | D10: =SUM(D5:D9) | E10: =SUM(E5:E9) | F10: =SUM(F5:F9) | G10: 100%
A12: DOCUMENT VERIFIED TOTALS (From Executive Report)
A13: Category | B13: Value | C13: Source
A14: Total Revenue Growth | B14: 76200000 | C14: Page 17
A15: Total Cost Reduction | B15: 28600000 | C15: Page 17
A16: Total Risk Reduction | B16: 4400000 | C16: Page 17
A17: Total Cash Flow | B17: 2700000 | C17: Page 17
A18: GRAND TOTAL ANNUAL BENEFIT | B18: 111900000 | C18: Page 1, 17
A20: VARIANCE CHECK (Calculated vs Document)
A21: Metric | B21: Calculated | C21: Document | D21: Variance
A22: Grand Total | B22: =F10 | C22: =B18 | D22: =B22-C22
A25: POST-TRANSFORMATION METRICS
A26: Metric | B26: Current State | C26: Post-Transform | D26: Change | E26: % Change
A27: Annual Revenue | B27: ='Company Baseline'!B7 | C27: 603000000 | D27: =C27-B27 | E27: =D27/B27
A28: Win Rate | B28: ='Company Baseline'!B17 | C28: 0.33 | D28: =C28-B28 | E28: =D28/B28
A29: Net Income | B29: ='Company Baseline'!B11 | C29: 147500000 | D29: =C29-B29 | E29: =D29/B29
A30: Net Margin | B30: ='Company Baseline'!B9 | C30: 0.24 | D30: =C30-B30 | E30: =D30/B30
A31: Annual Projects | B31: ='Company Baseline'!B15 | C31: 3600 | D31: =C31-B31 | E31: =D31/B31
A32: Leads Generated | B32: ='Company Baseline'!B24 | C32: 10000 | D32: =C32-B32 | E32: =D32/B32
A33: Cost Per Lead | B33: ='Company Baseline'!B25 | C33: 120 | D33: =C33-B33 | E33: =D33/B33

Sheet All Friction Points
A1: COMPLETE FRICTION POINT INVENTORY
A3: All friction points across all platforms with associated costs
A5: Platform | B5: Friction Category | C5: Specific Issue | D5: Business Impact | E5: Annual Cost
A6: P0 | B6: Speed to Lead | C6: Inbound leads sit in CRM inboxes for hours; conversion drops 80% after 5 minutes | D6: Lost conversions | E6: 4200000
A7: P0 | B7: Manual List Building | C7: SDRs waste 40% of time scraping permit sites and hail maps instead of selling | D7: 35% of sales time lost | E7: 2400000
A8: P0 | B8: Knowledge Gaps | C8: Junior reps struggle to answer technical questions (TPO vs EPDM), losing credibility | D8: Poor qualification | E8: 1500000
A9: P0 | B9: Data Silos | C9: Salesforce CRM disconnected from property, weather, permit data | D9: Missed timing | E9: 1200000
A10: P0 | B10: Seasonal Peaks | C10: Storm events create surge demand; can't scale manual outreach | D10: Lost emergency revenue | E10: 2800000
A11: P0 | B11: Customer Experience | C11: Inconsistent follow-up; leads go cold | D11: 40% lead leakage | E11: 3800000
A12: P1 | B12: Knowledge Gaps | C12: No visibility into which bids to pursue vs. walk away | D12: 22% win rate (below potential) | E12: 14400000
A13: P1 | B13: Data Silos | C13: Competitor pricing/strategies unknown | D13: Losing winnable deals | E13: 7200000
A14: P1 | B14: Low-Value Work | C14: Manual competitor research takes 3+ hours per bid | D14: Reduced bid capacity | E14: 2100000
A15: P2 | B15: Low-Value Repetitive Work | C15: NR Bid Sheet and proposal creation takes 2.5 hours each | D15: 14,000 hours/year | E15: 6700000
A16: P2 | B16: Knowledge Gaps | C16: Edge Estimate difficult to use with steep learning curve | D16: Bottleneck on experts | E16: 5100000
A17: P2 | B17: Rework and Errors | C17: Takeoff errors (measurements, quantities, roof depth, pipes, curbing, skylights) | D17: Project overruns | E17: 4400000
... A25: P4 | B25: Data Silos | C25: Spec requirements not linked to Edge items systematically | D25: Manual lookup errors | E25: 1400000
A26: TOTAL FRICTION COST | E26: =SUM(E6:E25)

Sheet All KPIs
A1: COMPLETE KPI INVENTORY
A3: All KPIs across all platforms with baseline, target, and improvement
A5: Platform | B5: Use Case | C5: KPI | D5: Baseline | E5: Target | F5: Improvement
A6: P0 | B6: Lead Generation | C6: Speed to Lead | D6: 4 hours | E6: <2 minutes | F6: 99%+
A7: P0 | B7: Lead Generation | C7: Cost Per Lead (CPL) | D7: $350 | E7: $120 | F7: 66%
A8: P0 | B8: Lead Generation | C8: Lead Volume (Annual) | D8: 2,400 | E8: 10,000+ | F8: 317%
A9: P0 | B9: Lead Generation | C9: Conversion (Lead→Meeting) | D9: 5% | E9: 12% | F9: 140%
A10: P0 | B10: Lead Generation | C10: Maintenance Plan Attach Rate | D10: 10% | E10: 25% | F10: 150%
A11: P0 | B11: Lead Generation | C11: Sales Cycle Reduction | D11: - | E11: -14 days | F11: -
A12: P1 | B12: Bid Assignment | C12: Win Rate | D12: 22% | E12: 33% | F12: 50%
A13: P1 | B13: Bid Assignment | C13: Bid evaluation time (hours) | D13: 3.0 | E13: 0.5 | F13: 83%
A14: P1 | B14: Competitor Analysis | C14: Competitive insights/bid | D14: 2 | E14: 8 | F14: 300%
A15: P1 | B15: Competitor Scouting | C15: Market intel updates/week | D15: 1 | E15: Daily | F15: 700%
A16: P2 | B16: Proposal Creation | C16: Creation time (hours) | D16: 2.5 | E16: 0.33 | F16: 87%
... A28: P4 | B28: Spec-to-Edge Mapping | C28: Mapping accuracy | D28: 75% | E28: 95% | F28: 27%

Sheet Scenario Builder
A1: SCENARIO BUILDER - Compare Custom Scenarios vs Base Case
A3: Instructions: Modify the PURPLE cells in your scenario to see how changes affect the total benefit. Compare against the base case.
A5: KEY ASSUMPTIONS
A6: Parameter | B6: Base Case | C6: Your Scenario | D6: Difference | E6: % Change | F6: Impact on Total
A7: Annual Revenue | B7: ='Company Baseline'!B7 | C7: 527000000 | D7: =C7-B7 | E7: =IF(B7=0,0,D7/B7) | F7: -
A8: Gross Margin % | B8: ='Company Baseline'!B8 | C8: 0.35 | D8: =C8-B8 | E8: =IF(B8=0,0,D8/B8) | F8: -
A9: Net Margin % | B9: ='Company Baseline'!B9 | C9: 0.07 | D9: =C9-B9 | E9: =IF(B9=0,0,D9/B9) | F9: -
A10: Annual Projects | B10: ='Company Baseline'!B15 | C10: 2100 | D10: =C10-B10 | E10: =IF(B10=0,0,D10/B10) | F10: -
A11: Annual Bids | B11: ='Company Baseline'!B16 | C11: 11700 | D11: =C11-B11 | E11: =IF(B11=0,0,D11/B11) | F11: -
A12: Average Project Value | B12: ='Company Baseline'!B18 | C12: 250000 | D12: =C12-B12 | E12: =IF(B12=0,0,D12/B12) | F12: -
A13: Current Cost Per Lead | B13: ='Company Baseline'!B25 | C13: 350 | D13: =C13-B13 | E13: =IF(B13=0,0,D13/B13) | F13: -
A14: P0: Annual Leads Generated | B14: ='Platform 0'!B33 | C14: 10000 | D14: =C14-B14 | E14: =IF(B14=0,0,D14/B14) | F14: -
A15: P0: Lead-to-Meeting Rate | B15: ='Platform 0'!B34 | C15: 0.12 | D15: =C15-B15 | E15: =IF(B15=0,0,D15/B15) | F15: -
A16: P0: Meeting-to-Close Rate | B16: ='Platform 0'!B35 | C16: 0.2 | D16: =C16-B16 | E16: =IF(B16=0,0,D16/B16) | F16: -
A17: P0: Target CPL | B17: ='Platform 0'!B36 | C17: 120 | D17: =C17-B17 | E17: =IF(B17=0,0,D17/B17) | F17: -
A18: P0: Maintenance Attach Rate | B18: ='Platform 0'!B37 | C18: 0.25 | D18: =C18-B18 | E18: =IF(B18=0,0,D18/B18) | F18: -
A19: P1: Win Rate Improvement (pts) | B19: ='Platform 1'!B20 | C19: 11 | D19: =C19-B19 | E19: =IF(B19=0,0,D19/B19) | F19: -
A20: P2: Proposal Time Reduction | B20: =1-'Platform 2'!D24/'Platform 2'!C24 | C20: 0.87 | D20: =C20-B20 | E20: =IF(B20=0,0,D20/B20) | F20: -
A21: P3: Schedule Time Reduction | B21: =1-'Platform 3'!D26/'Platform 3'!C26 | C21: 0.75 | D21: =C21-B21 | E21: =IF(B21=0,0,D21/B21) | F21: -
A22: P4: Submittal Time Reduction | B22: =1-'Platform 4'!D24/'Platform 4'!C24 | C22: 0.85 | D22: =C22-B22 | E22: =IF(B22=0,0,D22/B22) | F22: -
A25: SCENARIO RESULTS COMPARISON
A26: Platform | B26: Base Case Benefit | C26: Scenario Benefit | D26: Difference | E26: % Change
A27: P0: AI Market Expansion | B27: ='Platform 0'!C65 | C27: =(C8*C9*C10*C6*C7)+(C7-C11)*C8+C8*C9*C10*C12*25000+500000 | D27: =C27-B27 | E27: =IF(B27=0,0,D27/B27)
A28: P1: AI Sales Intelligence | B28: ='Platform 1'!C56 | C28: =(C5*C13/100)*C6*C8*0.35+'Platform 1'!C54 | D28: =C28-B28 | E28: =IF(B28=0,0,D28/B28)
A29: P2: AI Estimation Suite | B29: ='Platform 2'!G38 | C29: ='Platform 2'!G38 | D29: =C29-B29 | E29: =IF(B29=0,0,D29/B29)
A30: P3: AI Project Management | B30: ='Platform 3'!G40 | C30: ='Platform 3'!G40 | D30: =C30-B30 | E30: =IF(B30=0,0,D30/B30)
A31: P4: AI Knowledge Management | B31: ='Platform 4'!E32 | C31: ='Platform 4'!E32 | D31: =C31-B31 | E31: =IF(B31=0,0,D31/B31)
A32: GRAND TOTAL | B32: =SUM(B27:B31) | C32: =SUM(C27:C31) | D32: =SUM(D27:D31) | E32: =IF(B32=0,0,D32/B32)
A35: KEY SCENARIO INSIGHTS
A36: Total Benefit Change | B36: =D32
A37: Percentage Change | B37: =E32
A38: Scenario vs Base | B38: =IF(D32>0,"BETTER",IF(D32<0,"WORSE","SAME"))

Sheet Sensitivity Analysis
A1: SENSITIVITY ANALYSIS - Impact of Key Variable Changes
A3: This analysis shows how changes in key variables affect the total annual benefit.
A5: WIN RATE SENSITIVITY (Platform 1 Driver)
A6: Win Rate | B6: Additional Wins | C6: Revenue Impact | D6: Total P1 Benefit | E6: Change from Base
A7: 0.25 | B7: =11700*(A7-0.22) | C7: =B7*250000*0.35 | D7: =C7+852000 | E7: =D7-$D$10
A8: 0.28 | B8: =11700*(A8-0.22) | C8: =B8*250000*0.35 | D8: =C8+852000 | E8: =D8-$D$10
A9: 0.3 | B9: =11700*(A9-0.22) | C9: =B9*250000*0.35 | D9: =C9+852000 | E9: =D9-$D$10
A10: 0.33 | B10: =11700*(A10-0.22) | C10: =B10*250000*0.35 | D10: =C10+852000 | E10: =D10-$D$10
A11: 0.35 | B11: =11700*(A11-0.22) | C11: =B11*250000*0.35 | D11: =C11+852000 | E11: =D11-$D$10
A12: 0.38 | B12: =11700*(A12-0.22) | C12: =B12*250000*0.35 | D12: =C12+852000 | E12: =D12-$D$10
A13: 0.4 | B13: =11700*(A13-0.22) | C13: =B13*250000*0.35 | D13: =C13+852000 | E13: =D13-$D$10
A15: LEAD VOLUME SENSITIVITY (Platform 0 Driver)
A16: Annual Leads | B16: Qualified Meetings | C16: New Projects | D16: Net Revenue | E16: Change from Base
A17: 5000 | B17: =A17*0.12 | C17: =B17*0.20 | D17: =C17*250000*0.07 | E17: =D17-$D$19
A18: 7500 | B18: =A18*0.12 | C18: =B18*0.20 | D18: =C18*250000*0.07 | E18: =D18-$D$19
A19: 10000 | B19: =A19*0.12 | C19: =B19*0.20 | D19: =C19*250000*0.07 | E19: =D19-$D$19
A20: 12500 | B20: =A20*0.12 | C20: =B20*0.20 | D20: =C20*250000*0.07 | E20: =D20-$D$19
A21: 15000 | B21: =A21*0.12 | C21: =B21*0.20 | D21: =C21*250000*0.07 | E21: =D21-$D$19
A22: 20000 | B22: =A22*0.12 | C22: =B22*0.20 | D22: =C22*250000*0.07 | E22: =D22-$D$19
A23: 25000 | B23: =A23*0.12 | C23: =B23*0.20 | D23: =C23*250000*0.07 | E23: =D23-$D$19
A25: COST PER LEAD SENSITIVITY (Platform 0 Cost Savings)
A26: Target CPL | B26: CPL Savings | C26: Annual Savings (10K leads) | D26: Total P0 Benefit | E26: Change from Base
A27: 80 | B27: =350-A27 | C27: =B27*10000 | D27: =4200000+C27+700000+1500000+500000 | E27: =D27-$D$29
A28: 100 | B28: =350-A28 | C28: =B28*10000 | D28: =4200000+C28+700000+1500000+500000 | E28: =D28-$D$29
A29: 120 | B29: =350-A29 | C29: =B29*10000 | D29: =4200000+C29+700000+1500000+500000 | E29: =D29-$D$29
A30: 140 | B30: =350-A30 | C30: =B30*10000 | D30: =4200000+C30+700000+1500000+500000 | E30: =D30-$D$29
A31: 160 | B31: =350-A31 | C31: =B31*10000 | D31: =4200000+C31+700000+1500000+500000 | E31: =D31-$D$29
A32: 180 | B32: =350-A32 | C32: =B32*10000 | D32: =4200000+C32+700000+1500000+500000 | E32: =D32-$D$29
A33: 200 | B33: =350-A33 | C33: =B33*10000 | D33: =4200000+C33+700000+1500000+500000 | E33: =D33-$D$29
A35: AVERAGE PROJECT VALUE SENSITIVITY (All Platforms)
A36: Avg Project Value | B36: P0 Revenue Impact | C36: P1 Revenue Impact | D36: Total Impact | E36: Change from Base
A37: 200000 | B37: =240*A37*0.07 | C37: =1287*A37*0.35 | D37: =B37+C37 | E37: =D37-$D$39
A38: 225000 | B38: =240*A38*0.07 | C38: =1287*A38*0.35 | D38: =B38+C38 | E38: =D38-$D$39
A39: 250000 | B39: =240*A39*0.07 | C39: =1287*A39*0.35 | D39: =B39+C39 | E39: =D39-$D$39
A40: 275000 | B40: =240*A40*0.07 | C40: =1287*A40*0.35 | D40: =B40+C40 | E40: =D40-$D$39
A41: 300000 | B41: =240*A41*0.07 | C41: =1287*A41*0.35 | D41: =B41+C41 | E41: =D41-$D$39
A42: 350000 | B42: =240*A42*0.07 | C42: =1287*A42*0.35 | D42: =B42+C42 | E42: =D42-$D$39
A43: 400000 | B43: =240*A43*0.07 | C43: =1287*A43*0.35 | D43: =B43+C43 | E43: =D43-$D$39
A45: SENSITIVITY SUMMARY - Impact of ±10% Change
A46: Variable | B46: Base Value | C46: -10% Impact | D46: +10% Impact | E46: Sensitivity Rating
...

Sheet Charts Dashboard
A1: EXECUTIVE CHARTS DASHBOARD
A3: PLATFORM BENEFIT DATA
A4: Platform | B4: Benefit ($M) | C4: % of Total
A5: P0: Market Expansion | B5: 35 | C5: 0.31
A6: P1: Sales Intelligence | B6: 24.2 | C6: 0.22
A7: P2: Estimation Suite | B7: 23.2 | C7: 0.21
A8: P3: Project Mgmt | B8: 21.6 | C8: 0.19
A9: P4: Knowledge Mgmt | B9: 7.9 | C9: 0.07
A10: TOTAL | B10: =SUM(B5:B9)
A13: BUSINESS DRIVER DATA
A14: Driver | B14: Benefit ($M) | C14: % of Total
A15: Revenue Growth | B15: 76.2 | C15: 0.68
A16: Cost Reduction | B16: 28.6 | C16: 0.26
A17: Risk Mitigation | B17: 4.4 | C17: 0.04
A18: Cash Flow | B18: 2.7 | C18: 0.02
A21: TRANSFORMATION METRICS
A22: Metric | B22: Current | C22: Post-Transform | D22: Improvement
A23: Revenue ($M) | B23: 527 | C23: 603 | D23: =C23-B23
A24: Win Rate | B24: 0.22 | C24: 0.33 | D24: =C24-B24
A25: Net Income ($M) | B25: 35.6 | C25: 147.5 | D25: =C25-B25
A26: Projects/Year | B26: 2100 | C26: 3600 | D26: =C26-B26
A27: Leads/Year | B27: 2400 | C27: 10000 | D27: =C27-B27
A28: Cost Per Lead | B28: 350 | C28: 120 | D28: =C28-B28
A31: ROI SUMMARY
A32: Metric | B32: Value
A33: Total Annual Benefit | B33: $111.9M
A34: Estimated Investment | B34: $5.0M
A35: Net Annual Return | B35: $106.9M
A36: ROI | B36: 2,138%
A37: Payback Period | B37: <4 months
